Workbook

Sheet Overview
B2: FOMC | C2: Federal Open Market Committee
B3: 7 | C3: members of the board of governors in Washington
B4: 1 | C4: president of the Federal Reserve Bank of New York
B5: 4 | C5: of the remaining 11 regional FED bank presidents
B6: 12 | C6: total votes
B9: The goal: | C9: Predict the interest rate decision of the FED.
C10: Do not try to predict the macro data like, CPI, unemployment, etc. but rather try to analyze how the voters for that decision voted in the past, based on the information they had back then, compare macro economic situation from past with current one, try to predict how they will vote today
B13: Board of Governors | O13: the governors also dissent sometimes but it is not possible to determine why based on the beige books
C14: Kevin Warsh | O14: but here are the patterns and maybe you can find something from their publications or from a presentation
C15: Philip Jefferson
C16: Michelle Bowman | O16: Michelle Bowman
C17: Michael Barr
C18: Lisa Cook | O18: September 2024: wanted a smaller cut than the committee (hawkish).
C19: Jerome Powell | O19: July 2025: wanted a cut instead of a hold (dovish).
C20: Christopher Waller | O20: She appears willing to dissent in either direction depending on her assessment.
B22: New York Fed president | O22: Christopher Waller
C23: John Williams
O24: Both dissents were dovish (wanted cuts while the committee held).
B25: Remaining regional FED presidents
C26: District | D26: President | E26: Group | F26: 2026 Voters | O26: Stephen Miran
C27: Boston | D27: Susan Collins | E27: 1 | F27: x
C28: Philadelphia | D28: Patrick Harker | E28: 1 | O28: Every recorded dissent was dovish.
C29: Cleveland | D29: Beth Hammack | E29: 2 | F29: x | O29: He consistently preferred more easing than the committee:
C30: Richmond | D30: Tom Barkin | E30: 1 | O30: three times by 50 bp instead of 25 bp,
C31: Atlanta | D31: Raphael Bostic | E31: 3 | F31: x | O31: three times by 25 bp instead of a hold.
C32: Chicago | D32: Austan Goolsbee | E32: 2
C33: St. Louis | D33: Alberto Musalem | E33: 3
C34: Minneapolis | D34: Neel Kashkari | E34: 4 | F34: x
C35: Kansas City | D35: Jeff Schmid | E35: 4
C36: Dallas | D36: Lorie Logan | E36: 3
C37: San Francisco | D37: Mary Daly | E37: 4

Sheet Decision making
B3: Board of governors | H3: Regional Fed presidents
C4: broad | I4: more nuanced view
C5: national statistics | I5: implement regional datapoints into decision making
C6: https://www.federalreserve.gov/monetarypolicy/monetary-policy-strategy-tools-and-communications-statement-on-longer-run-goals-monetary-policy-strategy-2025.htm
I8: Analyze the "Beige Book"
C9: This is implemented in the Macro model | I9: https://www.minneapolisfed.org/region-and-community/regional-economic-indicators/beige-book-archive
I13: This is going to be implemented in the Micro Model
I14: at a later point in time

Sheet Macro Model >>

Sheet Model Output
A1: SUMMARY OUTPUT
A3: Regression Statistics
A4: Multiple R | B4: 0.88888852
A5: R Square | B5: 0.7901228
A6: Adjusted R Square | B6: 0.7698121
A7: Standard Error | B7: 0.0014890437
A8: Observations | B8: 35
A10: ANOVA
B11: df | C11: SS | D11: MS | E11: F | F11: Significance F
A12: Regression | B12: 3 | C12: 0.00025876522 | D12: 8.6255072e-05 | E12: 38.901806 | F12: 1.2608759e-10
A13: Residual | B13: 31 | C13: 6.8734784e-05 | D13: 2.2172511e-06
A14: Total | B14: 34 | C14: 0.0003275
B16: Coefficients | C16: Standard Error | D16: t Stat | E16: P-value | F16: Lower 95% | G16: Upper 95% | H16: Lower 95.0% | I16: Upper 95.0%
A17: Intercept | B17: 0.0072916885 | C17: 0.0060876944 | D17: 1.197775 | E17: 0.24008284 | F17: -0.0051242462 | G17: 0.019707623 | H17: -0.0051242462 | I17: 0.019707623
A18: Change of CPE | B18: 0.092624465 | C18: 0.039199026 | D18: 2.3629277 | E18: 0.024585216 | F18: 0.012677523 | G18: 0.17257141 | H18: 0.012677523 | I18: 0.17257141
A19: Inflation Expecation 1y | B19: 0.21108179 | C19: 0.050178567 | D19: 4.2066126 | E19: 0.00020505787 | F19: 0.10874193 | G19: 0.31342165 | H19: 0.10874193 | I19: 0.31342165
A20: Unemployment rate | B20: -0.0039622231 | C20: 0.0012816359 | D20: -3.0915357 | E20: 0.0041877754 | F20: -0.0065761367 | G20: -0.0013483095 | H20: -0.0065761367 | I20: -0.0013483095

Sheet Regression Model
H4: Inflation | K4: Labor market
C5: Meeting | D5: Decision | E5: New Fund Rate | F5: Change | I5: Change of CPE | J5: Inflation Expecation 1y | K5: Unemployment rate
C6: April | D6: hold | E6: 0.0375 | F6: =E6-E7 -> 0 | I6: ='Input data'!I6 -> 0.03082121 | J6: 0.032763981 | K6: ='Input data'!L6 -> 4.3
C7: March | D7: hold | E7: 0.0375 | F7: =E7-E8 -> 0 | I7: ='Input data'!I7 -> 0.032538498 | J7: 0.022952952 | K7: ='Input data'!L7 -> 4.3
B8: 2026 | C8: January | D8: hold | E8: 0.0375 | F8: =E8-E9 -> 0 | I8: ='Input data'!I8 -> 0.031046578 | J8: 0.025863954 | K8: ='Input data'!L8 -> 4.3
C9: December | D9: decrease | E9: 0.0375 | F9: =E9-E10 -> -0.0025 | I9: ='Input data'!I9 -> 0.029711102 | J9: 0.031928688 | K9: ='Input data'!L9 -> 4.4
C10: October | D10: decrease | E10: 0.04 | F10: =E10-E11 -> -0.0025 | I10: ='Input data'!I10 -> 0.026467789 | J10: 0.027275976 | K10: =(K9+K11)/2 -> 4.4
C11: September | D11: decrease | E11: 0.0425 | F11: =E11-E12 -> -0.0025 | I11: ='Input data'!I11 -> 0.028250692 | J11: 0.028035993 | K11: ='Input data'!L11 -> 4.4
C12: July | D12: hold | E12: 0.045 | F12: =E12-E13 -> 0 | I12: ='Input data'!I12 -> 0.028630472 | J12: 0.027890473 | K12: ='Input data'!L12 -> 4.3
C13: June | D13: hold | E13: 0.045 | F13: =E13-E14 -> 0 | I13: ='Input data'!I13 -> 0.028073722 | J13: 0.02380542 | K13: ='Input data'!L13 -> 4.1
C14: May | D14: hold | E14: 0.045 | F14: =E14-E15 -> 0 | I14: ='Input data'!I14 -> 0.028502747 | J14: 0.026913373 | K14: ='Input data'!L14 -> 4.3
C15: March | D15: hold | E15: 0.045 | F15: =E15-E16 -> 0 | I15: ='Input data'!I15 -> 0.026702948 | J15: 0.021838527 | K15: ='Input data'!L15 -> 4.2
B16: 2025 | C16: January | D16: hold | E16: 0.045 | F16: =E16-E17 -> 0 | I16: ='Input data'!I16 -> 0.027801381 | J16: 0.026269584 | K16: ='Input data'!L16 -> 4
C17: December | D17: decrease | E17: 0.045 | F17: =E17-E18 -> -0.0025 | I17: ='Input data'!I17 -> 0.029885896 | J17: 0.026503563 | K17: ='Input data'!L17 -> 4.1
C18: November | D18: decrease | E18: 0.0475 | F18: =E18-E19 -> -0.0025 | I18: ='Input data'!I18 -> 0.030946183 | J18: 0.024316758 | K18: ='Input data'!L18 -> 4.2
C19: September | D19: decrease | E19: 0.05 | F19: =E19-E20 -> -0.005 | I19: ='Input data'!I19 -> 0.02838628 | J19: 0.022361209 | K19: ='Input data'!L19 -> 4.1
C20: July | D20: hold | E20: 0.055 | F20: =E20-E21 -> 0 | I20: ='Input data'!I20 -> 0.028062163 | J20: 0.025556443 | K20: ='Input data'!L20 -> 4.2
C21: June | D21: hold | E21: 0.055 | F21: =E21-E22 -> 0 | I21: ='Input data'!I21 -> 0.027531619 | J21: 0.027258402 | K21: ='Input data'!L21 -> 4.1
C22: April | D22: hold | E22: 0.055 | F22: =E22-E23 -> 0 | I22: ='Input data'!I22 -> 0.027048361 | J22: 0.027043669 | K22: ='Input data'!L22 -> 3.9
C23: March | D23: hold | E23: 0.055 | F23: =E23-E24 -> 0 | I23: ='Input data'!I23 -> 0.031221739 | J23: 0.020822133 | K23: ='Input data'!L23 -> 3.9
B24: 2024 | C24: January | D24: hold | E24: 0.055 | F24: =E24-E25 -> 0 | I24: ='Input data'!I24 -> 0.027881183 | J24: 0.024186326 | K24: ='Input data'!L24 -> 3.7
C25: December | D25: hold | E25: 0.055 | F25: =E25-E26 -> 0 | I25: ='Input data'!I25 -> 0.03112388 | J25: 0.03091665 | K25: ='Input data'!L25 -> 3.8
C26: October | D26: hold | E26: 0.055 | F26: =E26-E27 -> 0 | I26: ='Input data'!I26 -> 0.03176619 | J26: 0.027695737 | K26: ='Input data'!L26 -> 3.9
C27: September | D27: hold | E27: 0.055 | F27: =E27-E28 -> 0 | I27: ='Input data'!I27 -> 0.036877742 | J27: 0.028124348 | K27: ='Input data'!L27 -> 3.7
C28: July | D28: increase | E28: 0.055 | F28: =E28-E29 -> 0.0025 | I28: ='Input data'!I28 -> 0.042991241 | J28: 0.024743165 | K28: ='Input data'!L28 -> 3.5
C29: June | D29: hold | E29: 0.0525 | F29: =E29-E30 -> 0 | I29: ='Input data'!I29 -> 0.043837868 | J29: 0.013662625 | K29: ='Input data'!L29 -> 3.6
C30: May | D30: increase | E30: 0.0525 | F30: =E30-E31 -> 0.0025 | I30: ='Input data'!I30 -> 0.047316254 | J30: 0.026536386 | K30: ='Input data'!L30 -> 3.6
C31: March | D31: increase | E31: 0.05 | F31: =E31-E32 -> 0.0025 | I31: ='Input data'!I31 -> 0.047832864 | J31: 0.020732509 | K31: ='Input data'!L31 -> 3.5
B32: 2023 | C32: February | D32: increase | E32: 0.0475 | F32: =E32-E33 -> 0.0025 | I32: ='Input data'!I32 -> 0.053163178 | J32: 0.026130895 | K32: ='Input data'!L32 -> 3.6
C33: December | D33: increase | E33: 0.045 | F33: =E33-E34 -> 0.005 | I33: ='Input data'!I33 -> 0.049668815 | J33: 0.028681192 | K33: ='Input data'!L33 -> 3.5
C34: November | D34: increase | E34: 0.04 | F34: =E34-E35 -> 0.0075 | I34: ='Input data'!I34 -> 0.052080888 | J34: 0.032390484 | K34: ='Input data'!L34 -> 3.6
C35: September | D35: increase | E35: 0.0325 | F35: =E35-E36 -> 0.0075 | I35: ='Input data'!I35 -> 0.056064793 | J35: 0.041791497 | K35: ='Input data'!L35 -> 3.5
C36: July | D36: increase | E36: 0.025 | F36: =E36-E37 -> 0.0075 | I36: ='Input data'!I36 -> 0.051073741 | J36: 0.033092777 | K36: ='Input data'!L36 -> 3.5
C37: June | D37: increase | E37: 0.0175 | F37: =E37-E38 -> 0.0075 | I37: ='Input data'!I37 -> 0.053156911 | J37: 0.042267134 | K37: ='Input data'!L37 -> 3.6
C38: May | D38: increase | E38: 0.01 | F38: =E38-E39 -> 0.005 | I38: ='Input data'!I38 -> 0.057131966 | J38: 0.036346578 | K38: ='Input data'!L38 -> 3.6
C39: March | D39: increase | E39: 0.005 | F39: =E39-E40 -> 0.0025 | I39: ='Input data'!I39 -> 0.055932219 | J39: 0.030576988 | K39: ='Input data'!L39 -> 3.7
B40: 2022 | C40: January | D40: hold | E40: 0.0025 | F40: =E40-E41 -> 0 | I40: ='Input data'!I40 -> 0.053584366 | J40: 0.022417585 | K40: ='Input data'!L40 -> 4
C41: December | D41: hold | E41: 0.0025 | F41: =E41-E42 -> 0 | J41: 0.026203086 | K41: ='Input data'!L41 -> 3.9
C42: November | D42: hold | E42: 0.0025 | F42: =E42-E43 -> 0 | J42: 0.024798405 | K42: ='Input data'!L42 -> 4.1
C43: September | D43: hold | E43: 0.0025 | F43: =E43-E44 -> 0 | J43: 0.026841371 | K43: ='Input data'!L43 -> 4.7
...

Sheet Input data
C2: Link to source | E2: After testing all variables, only the relevant ones are transferred to the Regression Model tab
C3: https://www.federalreserve.gov/monetarypolicy/fomccalendars.htm
G4: Inflation | K4: Labor market | O4: Economic activity | S4: Financial conditions
C5: Meeting | D5: Decision | E5: New Fund Rate | F5: Change | H5: Core PCE | I5: Change of CPE | J5: Inflation expectation 1y | L5: Unemployment rate | M5: Nonfarm payrolls | O5: GDP | P5: YoY GDP growth | Q5: Industrial production | S5: Treasury yields | T5: Corporate credit spreads | U5: Dollar strength
C6: April | D6: hold | E6: 0.0375 | F6: =E6-E7 -> 0 | H6: 129.667 | I6: =(H6/H14-1) -> 0.03082121 | J6: 0.032763981 | L6: 4.3 | S6: 0.044
C7: March | D7: hold | E7: 0.0375 | F7: =E7-E8 -> 0 | H7: 129.343 | I7: =(H7/H15-1) -> 0.032538498 | J7: 0.022952952 | L7: 4.3 | O7: 31865.721 | P7: =((O7/O9)^4)-1 -> 0.057622351 | S7: 0.043
B8: 2026 | C8: January | D8: hold | E8: 0.0375 | F8: =E8-E9 -> 0 | H8: 128.455 | I8: =(H8/H16-1) -> 0.031046578 | J8: 0.025863954 | L8: 4.3 | O8: 31865.721 | P8: =((O8/O10)^4)-1 -> 0.057622351 | S8: 0.0426
C9: December | D9: decrease | E9: 0.0375 | F9: =E9-E10 -> -0.0025 | H9: 127.886 | I9: =(H9/H17-1) -> 0.029711102 | J9: 0.031928688 | L9: 4.4 | O9: 31422.526 | P9: =((O9/O11)^4)-1 -> 0.04239671 | S9: 0.0418
C10: Ocotber | D10: decrease | E10: 0.04 | F10: =E10-E11 -> -0.0025 | H10: 127.243 | I10: =(H10/H18-1) -> 0.026467789 | J10: 0.027275976 | L10: n.a. | O10: 31422.526 | P10: =((O10/O12)^4)-1 -> 0.04239671 | S10: 0.0411
C11: September | D11: decrease | E11: 0.0425 | F11: =E11-E12 -> -0.0025 | H11: 126.954 | I11: =(H11/H19-1) -> 0.028250692 | J11: 0.028035993 | L11: 4.4 | O11: 31098.027 | P11: =((O11/O13)^4)-1 -> 0.08279192 | S11: 0.0416
C12: July | D12: hold | E12: 0.045 | F12: =E12-E13 -> 0 | H12: 126.43 | I12: =(H12/H20-1) -> 0.028630472 | J12: 0.027890473 | L12: 4.3 | O12: 31098.027 | P12: =((O12/O14)^4)-1 -> 0.08279192 | S12: 0.0437
C13: June | D13: hold | E13: 0.045 | F13: =E13-E14 -> 0 | H13: 126.121 | I13: =(H13/H21-1) -> 0.028073722 | J13: 0.02380542 | L13: 4.1 | O13: 30485.729 | P13: =((O13/O15)^4)-1 -> 0.060387104 | S13: 0.0424
C14: May | D14: hold | E14: 0.045 | F14: =E14-E15 -> 0 | H14: 125.79 | I14: =(H14/H22-1) -> 0.028502747 | J14: 0.026913373 | L14: 4.3 | O14: 30485.729 | P14: =((O14/O16)^4)-1 -> 0.060387104 | S14: 0.0441
C15: March | D15: hold | E15: 0.045 | F15: =E15-E16 -> 0 | H15: 125.267 | I15: =(H15/H23-1) -> 0.026702948 | J15: 0.021838527 | L15: 4.2 | O15: 30042.113 | P15: =((O15/O17)^4)-1 -> 0.029412627 | S15: 0.0423
B16: 2025 | C16: January | D16: hold | E16: 0.045 | F16: =E16-E17 -> 0 | H16: 124.587 | I16: =(H16/H24-1) -> 0.027801381 | J16: 0.026269584 | L16: 4 | O16: 30042.113 | P16: =((O16/O18)^4)-1 -> 0.029412627 | S16: 0.0458
C17: December | D17: decrease | E17: 0.045 | F17: =E17-E18 -> -0.0025 | H17: 124.196 | I17: =(H17/H25-1) -> 0.029885896 | J17: 0.026503563 | L17: 4.1 | O17: 29825.182 | P17: =((O17/O19)^4)-1 -> 0.043176078 | S17: 0.0458
C18: November | D18: decrease | E18: 0.0475 | F18: =E18-E19 -> -0.0025 | H18: 123.962 | I18: =(H18/H26-1) -> 0.030946183 | J18: 0.024316758 | L18: 4.2 | O18: 29825.182 | P18: =((O18/O20)^4)-1 -> 0.043176078 | S18: 0.0418
C19: September | D19: decrease | E19: 0.05 | F19: =E19-E20 -> -0.005 | H19: 123.466 | I19: =(H19/H27-1) -> 0.02838628 | J19: 0.022361209 | L19: 4.1 | O19: 29511.664 | P19: =((O19/O21)^4)-1 -> 0.0509855 | S19: 0.0381
C20: July | D20: hold | E20: 0.055 | F20: =E20-E21 -> 0 | H20: 122.911 | I20: =(H20/H28-1) -> 0.028062163 | J20: 0.025556443 | L20: 4.2 | O20: 29511.664 | P20: =((O20/O22)^4)-1 -> 0.0509855 | S20: 0.0409
C21: June | D21: hold | E21: 0.055 | F21: =E21-E22 -> 0 | H21: 122.677 | I21: =(H21/H29-1) -> 0.027531619 | J21: 0.027258402 | L21: 4.1 | O21: 29147.044 | P21: =((O21/O23)^4)-1 -> 0.062567611 | S21: 0.0436
C22: April | D22: hold | E22: 0.055 | F22: =E22-E23 -> 0 | H22: 122.304 | I22: =(H22/H30-1) -> 0.027048361 | J22: 0.027043669 | L22: 3.9 | O22: 29147.044 | P22: =((O22/O24)^4)-1 -> 0.062567611 | S22: 0.0469
C23: March | D23: hold | E23: 0.055 | F23: =E23-E24 -> 0 | H23: 122.009 | I23: =(H23/H31-1) -> 0.031221739 | J23: 0.020822133 | L23: 3.9 | O23: 28708.161 | P23: =((O23/O25)^4)-1 -> 0.040486834 | S23: 0.042
B24: 2024 | C24: January | D24: hold | E24: 0.055 | F24: =E24-E25 -> 0 | H24: 121.217 | I24: =(H24/H32-1) -> 0.027881183 | J24: 0.024186326 | L24: 3.7 | O24: 28708.161 | P24: =((O24/O26)^4)-1 -> 0.040486834 | S24: 0.0399
C25: December | D25: hold | E25: 0.055 | F25: =E25-E26 -> 0 | H25: 120.592 | I25: =(H25/H33-1) -> 0.03112388 | J25: 0.03091665 | L25: 3.8 | O25: 28424.722 | P25: =((O25/O27)^4)-1 -> 0.050788649 | S25: 0.0388
C26: Ocotber | D26: hold | E26: 0.055 | F26: =E26-E27 -> 0 | H26: 120.241 | I26: =(H26/H34-1) -> 0.03176619 | J26: 0.027695737 | L26: 3.9 | O26: 28424.722 | P26: =((O26/O28)^4)-1 -> 0.050788649 | S26: 0.0488
C27: September | D27: hold | E27: 0.055 | F27: =E27-E28 -> 0 | H27: 120.058 | I27: =(H27/H35-1) -> 0.036877742 | J27: 0.028124348 | L27: 3.7 | O27: 28074.846 | P27: =((O27/O29)^4)-1 -> 0.081536584 | S27: 0.0459
C28: July | D28: increase | E28: 0.055 | F28: =E28-E29 -> 0.0025 | H28: 119.556 | I28: =(H28/H36-1) -> 0.042991241 | J28: 0.024743165 | L28: 3.5 | O28: 28074.846 | P28: =((O28/O30)^4)-1 -> 0.081536584 | S28: 0.0397
C29: June | D29: hold | E29: 0.0525 | F29: =E29-E30 -> 0 | H29: 119.39 | I29: =(H29/H37-1) -> 0.043837868 | J29: 0.013662625 | L29: 3.6 | O29: 27530.055 | P29: =((O29/O31)^4)-1 -> 0.04689404 | S29: 0.0381
C30: May | D30: increase | E30: 0.0525 | F30: =E30-E31 -> 0.0025 | H30: 119.083 | I30: =(H30/H38-1) -> 0.047316254 | J30: 0.026536386 | L30: 3.6 | O30: 27530.055 | P30: =((O30/O32)^4)-1 -> 0.04689404 | S30: 0.0364
C31: March | D31: increase | E31: 0.05 | F31: =E31-E32 -> 0.0025 | H31: 118.315 | I31: =(H31/H39-1) -> 0.047832864 | J31: 0.020732509 | L31: 3.5 | O31: 27216.445 | P31: =((O31/O33)^4)-1 -> 0.068313581 | S31: 0.0348
B32: 2023 | C32: February | D32: increase | E32: 0.0475 | F32: =E32-E33 -> 0.0025 | H32: 117.929 | I32: =(H32/H40-1) -> 0.053163178 | J32: 0.026130895 | L32: 3.6 | O32: 27216.445 | P32: =((O32/O34)^4)-1 -> 0.068313581 | S32: 0.0392
C33: December | D33: increase | E33: 0.045 | F33: =E33-E34 -> 0.005 | H33: 116.952 | I33: =(H33/H41-1) -> 0.049668815 | J33: 0.028681192 | L33: 3.5 | O33: 26770.514 | P33: =((O33/O35)^4)-1 -> 0.067597462 | S33: 0.0388
C34: November | D34: increase | E34: 0.04 | F34: =E34-E35 -> 0.0075 | H34: 116.539 | I34: =(H34/H42-1) -> 0.052080888 | J34: 0.032390484 | L34: 3.6 | O34: 26770.514 | P34: =((O34/O36)^4)-1 -> 0.067597462 | S34: 0.0368
C35: September | D35: increase | E35: 0.0325 | F35: =E35-E36 -> 0.0075 | H35: 115.788 | I35: =(H35/H43-1) -> 0.056064793 | J35: 0.041791497 | L35: 3.5 | O35: 26336.304 | P35: =((O35/O37)^4)-1 -> 0.075519861 | S35: 0.0383
C36: July | D36: increase | E36: 0.025 | F36: =E36-E37 -> 0.0075 | H36: 114.628 | I36: =(H36/H44-1) -> 0.051073741 | J36: 0.033092777 | L36: 3.5 | O36: 26336.304 | P36: =((O36/O38)^4)-1 -> 0.075519861 | S36: 0.0267
C37: June | D37: increase | E37: 0.0175 | F37: =E37-E38 -> 0.0075 | H37: 114.376 | I37: =(H37/H45-1) -> 0.053156911 | J37: 0.042267134 | L37: 3.6 | O37: 25861.292 | P37: =((O37/O39)^4)-1 -> 0.10035157 | S37: 0.0298
C38: May | D38: increase | E38: 0.01 | F38: =E38-E39 -> 0.005 | H38: 113.703 | I38: =(H38/H46-1) -> 0.057131966 | J38: 0.036346578 | L38: 3.6 | O38: 25861.292 | P38: =((O38/O40)^4)-1 -> 0.10035157 | S38: 0.0285
C39: March | D39: increase | E39: 0.005 | F39: =E39-E40 -> 0.0025 | H39: 112.914 | I39: =(H39/H47-1) -> 0.055932219 | J39: 0.030576988 | L39: 3.7 | O39: 25250.347 | P39: =((O39/O41)^4)-1 -> 0.072285158 | S39: 0.0232
B40: 2022 | C40: January | D40: hold | E40: 0.0025 | F40: =E40-E41 -> 0 | H40: 111.976 | I40: =(H40/H48-1) -> 0.053584366 | J40: 0.022417585 | L40: 4 | O40: 25250.347 | P40: =((O40/O42)^4)-1 -> 0.072285158 | S40: 0.0179
C41: December | D41: hold | E41: 0.0025 | F41: =E41-E42 -> 0 | H41: 111.418 | J41: 0.026203086 | L41: 3.9 | O41: 24813.6 | P41: =((O41/O43)^4)-1 -> 0.14601436 | S41: 0.0152
...

Sheet Micro Model >>

Sheet Output
A1: SUMMARY OUTPUT | B1: based on tampered input
A3: Regression Statistics
A4: Multiple R | B4: 0.34622447
A5: R Square | B5: 0.11987139
A6: Adjusted R Square | B6: 0.10963733
A7: Standard Error | B7: 0.27739045
A8: Observations | B8: 175
A10: ANOVA
B11: df | C11: SS | D11: MS | E11: F | F11: Significance F
A12: Regression | B12: 2 | C12: 1.8025231 | D12: 0.90126157 | E12: 11.712992 | F12: 1.7020335e-05
A13: Residual | B13: 172 | C13: 13.23462 | D13: 0.076945463
A14: Total | B14: 174 | C14: 15.037143
B16: Coefficients | C16: Standard Error | D16: t Stat | E16: P-value | F16: Lower 95% | G16: Upper 95% | H16: Lower 95.0% | I16: Upper 95.0%
A17: Intercept | B17: -0.055968442 | C17: 0.03753257 | D17: -1.4911966 | E17: 0.13774159 | F17: -0.13005219 | G17: 0.018115303 | H17: -0.13005219 | I17: 0.018115303
A18: Employment | B18: 0.072727926 | C18: 0.030975583 | D18: 2.3479114 | E18: 0.020016212 | F18: 0.011586704 | G18: 0.13386915 | H18: 0.011586704 | I18: 0.13386915
A19: Prices | B19: 0.11870212 | C19: 0.032450511 | D19: 3.6579431 | E19: 0.00033776338 | F19: 0.05464961 | G19: 0.18275463 | H19: 0.05464961 | I19: 0.18275463

Sheet tampered Input
C2: here I simply replaced all "NA" with 0 but that's obviously wrong
H3: Economic conditions
C4: Meeting | D4: Regio0l Member | E4: Vote for a change of | F4: FFR change | H4: Economic Activity | I4: Employment | J4: Prices
B5: https://www.minneapolisfed.org/beige-book-reports/2026/2026-01-su | C5: April | D5: New York | E5: 0 | F5: 0 | H5: -1 | I5: -1 | J5: 1
C6: April | D6: Philadelphia | E6: 0 | F6: 0 | H6: 1 | I6: 1 | J6: 1
C7: April | D7: Cleveland | E7: 0 | F7: 0 | H7: 1 | I7: 0 | J7: 1
C8: April | D8: Minneapolis | E8: 0 | F8: 0 | H8: 0 | I8: -1 | J8: 1
C9: April | D9: Dallas | E9: 0 | F9: 0 | H9: 0 | I9: 0 | J9: 1
B10: https://www.minneapolisfed.org/beige-book-reports/2026/2026-03-su | C10: March | D10: New York | E10: 0 | F10: 0 | H10: -1 | I10: 0 | J10: 1
C11: March | D11: Philadelphia | E11: 0 | F11: 0 | H11: 1 | I11: 1 | J11: 1
C12: March | D12: Cleveland | E12: 0 | F12: 0 | H12: 1 | I12: 0 | J12: 1
C13: March | D13: Minneapolis | E13: 0 | F13: 0 | H13: -1 | I13: -1 | J13: 1
C14: March | D14: Dallas | E14: 0 | F14: 0 | H14: 1 | I14: 1 | J14: 2
C15: January | D15: New York | E15: 0 | F15: 0 | H15: -1 | I15: 0 | J15: 1
C16: January | D16: Philadelphia | E16: 0 | F16: 0 | H16: 1 | I16: -1 | J16: 1
C17: January | D17: Cleveland | E17: 0 | F17: 0 | H17: 1 | I17: 1 | J17: 1
C18: January | D18: Minneapolis | E18: 0 | F18: 0 | H18: 1 | I18: 1 | J18: 1
B19: 2026 | C19: January | D19: Dallas | E19: 0 | F19: 0 | H19: 1 | I19: 1 | J19: 2
B20: https://www.minneapolisfed.org/beige-book-reports/2025/2025-11-su | C20: December | D20: New York | E20: -0.25 | F20: -0.25 | H20: -1 | I20: -1 | J20: 1
C21: December | D21: Boston | E21: -0.25 | F21: -0.25 | H21: 1 | I21: -1 | J21: 1
C22: December | D22: Chicago | E22: 0 | F22: -0.25 | H22: 1 | I22: 1 | J22: 1
C23: December | D23: St. Louis | E23: -0.25 | F23: -0.25 | H23: 0 | I23: 0 | J23: 1
C24: December | D24: Kansas City | E24: 0 | F24: -0.25 | H24: -1 | I24: 0 | J24: 1
B25: https://www.minneapolisfed.org/beige-book-reports/2025/2025-10-su | C25: Ocotber | D25: New York | E25: -0.25 | F25: -0.25 | H25: -1 | I25: 0 | J25: 1
C26: Ocotber | D26: Boston | E26: -0.25 | F26: -0.25 | H26: 1 | I26: 0 | J26: 1
C27: Ocotber | D27: Chicago | E27: -0.25 | F27: -0.25 | H27: 0 | I27: 0 | J27: 1
C28: Ocotber | D28: St. Louis | E28: -0.25 | F28: -0.25 | H28: 0 | I28: 0 | J28: 1
C29: Ocotber | D29: Kansas City | E29: 0 | F29: -0.25 | H29: -1 | I29: -1 | J29: 0
B30: https://www.minneapolisfed.org/beige-book-reports/2025/2025-09-su | C30: September | D30: New York | E30: -0.25 | F30: -0.25 | H30: -1 | I30: 0 | J30: 1
C31: September | D31: Boston | E31: -0.25 | F31: -0.25 | H31: 1 | I31: -1 | J31: 1
C32: September | D32: Chicago | E32: -0.25 | F32: -0.25 | H32: 1 | I32: 1 | J32: 1
C33: September | D33: St. Louis | E33: -0.25 | F33: -0.25 | H33: 0 | I33: 0 | J33: 1
C34: September | D34: Kansas City | E34: -0.25 | F34: -0.25 | H34: 0 | I34: -1 | J34: 1
B35: https://www.minneapolisfed.org/beige-book-reports/2025/2025-07-su | C35: July | D35: New York | E35: 0 | F35: 0 | H35: -1 | I35: 1 | J35: 1
C36: July | D36: Boston | E36: 0 | F36: 0 | H36: 0 | I36: 0 | J36: 1
C37: July | D37: Chicago | E37: 0 | F37: 0 | H37: 1 | I37: 1 | J37: 1
C38: July | D38: St. Louis | E38: 0 | F38: 0 | H38: 0 | I38: 0 | J38: 1
C39: July | D39: Kansas City | E39: 0 | F39: 0 | H39: 0 | I39: 0 | J39: 1
B40: https://www.minneapolisfed.org/beige-book-reports/2025/2025-06-su | C40: June | D40: New York | E40: 0 | F40: 0 | H40: -1 | I40: 0 | J40: 1
C41: June | D41: Boston | E41: 0 | F41: 0 | H41: -1 | I41: -1 | J41: 1
...

Sheet Input
C2: next step: fix the NA
H3: Economic conditions
C4: Meeting | D4: Regional Member | E4: Vote for a change of | F4: FFR change | H4: Economic Activity | I4: Employment | J4: Prices
B5: https://www.minneapolisfed.org/beige-book-reports/2026/2026-01-su | C5: April | D5: New York | E5: 0 | F5: 0 | H5: -1 | I5: -1 | J5: 1
C6: April | D6: Philadelphia | E6: 0 | F6: 0 | H6: 1 | I6: 1 | J6: 1
C7: April | D7: Cleveland | E7: 0 | F7: 0 | H7: 1 | I7: NA | J7: 1
C8: April | D8: Minneapolis | E8: 0 | F8: 0 | H8: 0 | I8: -1 | J8: 1
C9: April | D9: Dallas | E9: 0 | F9: 0 | H9: 0 | I9: 0 | J9: 1
B10: https://www.minneapolisfed.org/beige-book-reports/2026/2026-03-su | C10: March | D10: New York | E10: 0 | F10: 0 | H10: -1 | I10: 0 | J10: 1
C11: March | D11: Philadelphia | E11: 0 | F11: 0 | H11: 1 | I11: 1 | J11: 1
C12: March | D12: Cleveland | E12: 0 | F12: 0 | H12: 1 | I12: NA | J12: 1
C13: March | D13: Minneapolis | E13: 0 | F13: 0 | H13: -1 | I13: -1 | J13: 1
C14: March | D14: Dallas | E14: 0 | F14: 0 | H14: 1 | I14: 1 | J14: 2
C15: January | D15: New York | E15: 0 | F15: 0 | H15: -1 | I15: 0 | J15: 1
C16: January | D16: Philadelphia | E16: 0 | F16: 0 | H16: 1 | I16: -1 | J16: 1
C17: January | D17: Cleveland | E17: 0 | F17: 0 | H17: 1 | I17: 1 | J17: 1
C18: January | D18: Minneapolis | E18: 0 | F18: 0 | H18: 1 | I18: 1 | J18: 1
B19: 2026 | C19: January | D19: Dallas | E19: 0 | F19: 0 | H19: 1 | I19: 1 | J19: 2
B20: https://www.minneapolisfed.org/beige-book-reports/2025/2025-11-su | C20: December | D20: New York | E20: -0.25 | F20: -0.25 | H20: -1 | I20: -1 | J20: 1
C21: December | D21: Boston | E21: -0.25 | F21: -0.25 | H21: 1 | I21: -1 | J21: 1
C22: December | D22: Chicago | E22: 0 | F22: -0.25 | H22: 1 | I22: 1 | J22: 1
C23: December | D23: St. Louis | E23: -0.25 | F23: -0.25 | H23: 0 | I23: 0 | J23: 1
C24: December | D24: Kansas City | E24: 0 | F24: -0.25 | H24: -1 | I24: 0 | J24: 1
B25: https://www.minneapolisfed.org/beige-book-reports/2025/2025-10-su | C25: Ocotber | D25: New York | E25: -0.25 | F25: -0.25 | H25: -1 | I25: 0 | J25: 1
C26: Ocotber | D26: Boston | E26: -0.25 | F26: -0.25 | H26: 1 | I26: 0 | J26: 1
C27: Ocotber | D27: Chicago | E27: -0.25 | F27: -0.25 | H27: 0 | I27: 0 | J27: 1
C28: Ocotber | D28: St. Louis | E28: -0.25 | F28: -0.25 | H28: 0 | I28: 0 | J28: 1
C29: Ocotber | D29: Kansas City | E29: 0 | F29: -0.25 | H29: -1 | I29: -1 | J29: NA
B30: https://www.minneapolisfed.org/beige-book-reports/2025/2025-09-su | C30: September | D30: New York | E30: -0.25 | F30: -0.25 | H30: -1 | I30: 0 | J30: 1
C31: September | D31: Boston | E31: -0.25 | F31: -0.25 | H31: 1 | I31: -1 | J31: 1
C32: September | D32: Chicago | E32: -0.25 | F32: -0.25 | H32: 1 | I32: 1 | J32: 1
C33: September | D33: St. Louis | E33: -0.25 | F33: -0.25 | H33: 0 | I33: 0 | J33: 1
C34: September | D34: Kansas City | E34: -0.25 | F34: -0.25 | H34: 0 | I34: -1 | J34: 1
B35: https://www.minneapolisfed.org/beige-book-reports/2025/2025-07-su | C35: July | D35: New York | E35: 0 | F35: 0 | H35: -1 | I35: 1 | J35: 1
C36: July | D36: Boston | E36: 0 | F36: 0 | H36: 0 | I36: NA | J36: 1
C37: July | D37: Chicago | E37: 0 | F37: 0 | H37: 1 | I37: 1 | J37: 1
C38: July | D38: St. Louis | E38: 0 | F38: 0 | H38: 0 | I38: 0 | J38: 1
C39: July | D39: Kansas City | E39: 0 | F39: 0 | H39: 0 | I39: NA | J39: 1
B40: https://www.minneapolisfed.org/beige-book-reports/2025/2025-06-su | C40: June | D40: New York | E40: 0 | F40: 0 | H40: -1 | I40: 0 | J40: 1
C41: June | D41: Boston | E41: 0 | F41: 0 | H41: -1 | I41: -1 | J41: 1
...

Sheet variable coding
C1: for classification of micro model variables
C3: Score | D3: Interpretation | E3: Typical wording
C4: 2 | D4: Strong increase / persistent upward pressure | E4: strong robust rapid accelerated surged widespread markedly sharply significant
C5: 1 | D5: Moderate or slight increase | E5: slightly modestly edged higher continued to increase picked up expanded slightly
C6: 0 | D6: Stable / little change | E6: stable unchanged flat little changed held steady
C7: −1 | D7: Moderate decline | E7: declined slightly softened eased slowed weakened
C8: −2 | D8: Strong decline | E8: contracted sharply fell substantially deteriorated rapidly severe decline
